[2024-12-12 18:39:40,332] INFO in _internal: [33mPress CTRL+C to quit[0m
[2024-12-12 18:39:40,334] INFO in _internal:  * Restarting with stat
[2024-12-12 18:39:40,559] WARNING in _internal:  * Debugger is active!
[2024-12-12 18:39:40,559]  * Debugger is active!
[2024-12-12 18:39:40,568] INFO in _internal:  * Debugger PIN: 111-422-814
[2024-12-12 18:39:40,568]  * Debugger PIN: 111-422-814
[2024-12-12 18:39:42,909] DEBUG in app: Request: GET http://127.0.0.1:8000/ - Params: ImmutableMultiDict([]) - Body: 
[2024-12-12 18:39:42,909] Request: GET http://127.0.0.1:8000/ - Params: ImmutableMultiDict([]) - Body: 
[2024-12-12 18:39:42,915] ERROR in app: Exception: 404 Not Found: The requested URL was not found on the server. If you entered the URL manually please check your spelling and try again.
Traceback (most recent call last):
  File "/Library/Frameworks/Python.framework/Versions/3.12/lib/python3.12/site-packages/flask/app.py", line 1484, in full_dispatch_request
    rv = self.dispatch_request()
         ^^^^^^^^^^^^^^^^^^^^^^^
  File "/Library/Frameworks/Python.framework/Versions/3.12/lib/python3.12/site-packages/flask/app.py", line 1458, in dispatch_request
    self.raise_routing_exception(req)
  File "/Library/Frameworks/Python.framework/Versions/3.12/lib/python3.12/site-packages/flask/app.py", line 1440, in raise_routing_exception
    raise request.routing_exception  # type: ignore
    ^^^^^^^^^^^^^^^^^^^^^^^^^^^^^^^
  File "/Library/Frameworks/Python.framework/Versions/3.12/lib/python3.12/site-packages/flask/ctx.py", line 353, in match_request
    result = self.url_adapter.match(return_rule=True)  # type: ignore
             ^^^^^^^^^^^^^^^^^^^^^^^^^^^^^^^^^^^^^^^^
  File "/Library/Frameworks/Python.framework/Versions/3.12/lib/python3.12/site-packages/werkzeug/routing/map.py", line 655, in match
    raise NotFound() from None
werkzeug.exceptions.NotFound: 404 Not Found: The requested URL was not found on the server. If you entered the URL manually please check your spelling and try again.
[2024-12-12 18:39:42,915] Exception: 404 Not Found: The requested URL was not found on the server. If you entered the URL manually please check your spelling and try again.
Traceback (most recent call last):
  File "/Library/Frameworks/Python.framework/Versions/3.12/lib/python3.12/site-packages/flask/app.py", line 1484, in full_dispatch_request
    rv = self.dispatch_request()
         ^^^^^^^^^^^^^^^^^^^^^^^
  File "/Library/Frameworks/Python.framework/Versions/3.12/lib/python3.12/site-packages/flask/app.py", line 1458, in dispatch_request
    self.raise_routing_exception(req)
  File "/Library/Frameworks/Python.framework/Versions/3.12/lib/python3.12/site-packages/flask/app.py", line 1440, in raise_routing_exception
    raise request.routing_exception  # type: ignore
    ^^^^^^^^^^^^^^^^^^^^^^^^^^^^^^^
  File "/Library/Frameworks/Python.framework/Versions/3.12/lib/python3.12/site-packages/flask/ctx.py", line 353, in match_request
    result = self.url_adapter.match(return_rule=True)  # type: ignore
             ^^^^^^^^^^^^^^^^^^^^^^^^^^^^^^^^^^^^^^^^
  File "/Library/Frameworks/Python.framework/Versions/3.12/lib/python3.12/site-packages/werkzeug/routing/map.py", line 655, in match
    raise NotFound() from None
werkzeug.exceptions.NotFound: 404 Not Found: The requested URL was not found on the server. If you entered the URL manually please check your spelling and try again.
[2024-12-12 18:39:42,920] DEBUG in app: Response: 500 INTERNAL SERVER ERROR - Data: An error occurred
[2024-12-12 18:39:42,920] Response: 500 INTERNAL SERVER ERROR - Data: An error occurred
[2024-12-12 18:39:42,921] INFO in _internal: 127.0.0.1 - - [12/Dec/2024 18:39:42] "[35m[1mGET / HTTP/1.1[0m" 500 -
[2024-12-12 18:39:42,921] 127.0.0.1 - - [12/Dec/2024 18:39:42] "[35m[1mGET / HTTP/1.1[0m" 500 -
[2024-12-12 18:39:43,032] DEBUG in app: Request: GET http://127.0.0.1:8000/favicon.ico - Params: ImmutableMultiDict([]) - Body: 
[2024-12-12 18:39:43,032] Request: GET http://127.0.0.1:8000/favicon.ico - Params: ImmutableMultiDict([]) - Body: 
[2024-12-12 18:39:43,032] ERROR in app: Exception: 404 Not Found: The requested URL was not found on the server. If you entered the URL manually please check your spelling and try again.
Traceback (most recent call last):
  File "/Library/Frameworks/Python.framework/Versions/3.12/lib/python3.12/site-packages/flask/app.py", line 1484, in full_dispatch_request
    rv = self.dispatch_request()
         ^^^^^^^^^^^^^^^^^^^^^^^
  File "/Library/Frameworks/Python.framework/Versions/3.12/lib/python3.12/site-packages/flask/app.py", line 1458, in dispatch_request
    self.raise_routing_exception(req)
  File "/Library/Frameworks/Python.framework/Versions/3.12/lib/python3.12/site-packages/flask/app.py", line 1440, in raise_routing_exception
    raise request.routing_exception  # type: ignore
    ^^^^^^^^^^^^^^^^^^^^^^^^^^^^^^^
  File "/Library/Frameworks/Python.framework/Versions/3.12/lib/python3.12/site-packages/flask/ctx.py", line 353, in match_request
    result = self.url_adapter.match(return_rule=True)  # type: ignore
             ^^^^^^^^^^^^^^^^^^^^^^^^^^^^^^^^^^^^^^^^
  File "/Library/Frameworks/Python.framework/Versions/3.12/lib/python3.12/site-packages/werkzeug/routing/map.py", line 655, in match
    raise NotFound() from None
werkzeug.exceptions.NotFound: 404 Not Found: The requested URL was not found on the server. If you entered the URL manually please check your spelling and try again.
[2024-12-12 18:39:43,032] Exception: 404 Not Found: The requested URL was not found on the server. If you entered the URL manually please check your spelling and try again.
Traceback (most recent call last):
  File "/Library/Frameworks/Python.framework/Versions/3.12/lib/python3.12/site-packages/flask/app.py", line 1484, in full_dispatch_request
    rv = self.dispatch_request()
         ^^^^^^^^^^^^^^^^^^^^^^^
  File "/Library/Frameworks/Python.framework/Versions/3.12/lib/python3.12/site-packages/flask/app.py", line 1458, in dispatch_request
    self.raise_routing_exception(req)
  File "/Library/Frameworks/Python.framework/Versions/3.12/lib/python3.12/site-packages/flask/app.py", line 1440, in raise_routing_exception
    raise request.routing_exception  # type: ignore
    ^^^^^^^^^^^^^^^^^^^^^^^^^^^^^^^
  File "/Library/Frameworks/Python.framework/Versions/3.12/lib/python3.12/site-packages/flask/ctx.py", line 353, in match_request
    result = self.url_adapter.match(return_rule=True)  # type: ignore
             ^^^^^^^^^^^^^^^^^^^^^^^^^^^^^^^^^^^^^^^^
  File "/Library/Frameworks/Python.framework/Versions/3.12/lib/python3.12/site-packages/werkzeug/routing/map.py", line 655, in match
    raise NotFound() from None
werkzeug.exceptions.NotFound: 404 Not Found: The requested URL was not found on the server. If you entered the URL manually please check your spelling and try again.
[2024-12-12 18:39:43,033] DEBUG in app: Response: 500 INTERNAL SERVER ERROR - Data: An error occurred
[2024-12-12 18:39:43,033] Response: 500 INTERNAL SERVER ERROR - Data: An error occurred
[2024-12-12 18:39:43,033] INFO in _internal: 127.0.0.1 - - [12/Dec/2024 18:39:43] "[35m[1mGET /favicon.ico HTTP/1.1[0m" 500 -
[2024-12-12 18:39:43,033] 127.0.0.1 - - [12/Dec/2024 18:39:43] "[35m[1mGET /favicon.ico HTTP/1.1[0m" 500 -
[2024-12-12 18:40:31,367] DEBUG in app: Request: GET http://127.0.0.1:8000/films - Params: ImmutableMultiDict([]) - Body: 
[2024-12-12 18:40:31,367] Request: GET http://127.0.0.1:8000/films - Params: ImmutableMultiDict([]) - Body: 
[2024-12-12 18:40:31,478] DEBUG in app: Response: 200 OK - Data: [
  {
    "dateRelease": "rwerwet",
    "filmName": "qwrqwrq",
    "genre": "ewrwer",
    "id": 1,
    "urlImage": 234
  }
]

[2024-12-12 18:40:31,478] Response: 200 OK - Data: [
  {
    "dateRelease": "rwerwet",
    "filmName": "qwrqwrq",
    "genre": "ewrwer",
    "id": 1,
    "urlImage": 234
  }
]

[2024-12-12 18:40:31,479] INFO in _internal: 127.0.0.1 - - [12/Dec/2024 18:40:31] "GET /films HTTP/1.1" 200 -
[2024-12-12 18:40:31,479] 127.0.0.1 - - [12/Dec/2024 18:40:31] "GET /films HTTP/1.1" 200 -
[2024-12-12 18:40:31,510] DEBUG in app: Request: GET http://127.0.0.1:8000/favicon.ico - Params: ImmutableMultiDict([]) - Body: 
[2024-12-12 18:40:31,510] Request: GET http://127.0.0.1:8000/favicon.ico - Params: ImmutableMultiDict([]) - Body: 
[2024-12-12 18:40:31,510] ERROR in app: Exception: 404 Not Found: The requested URL was not found on the server. If you entered the URL manually please check your spelling and try again.
Traceback (most recent call last):
  File "/Library/Frameworks/Python.framework/Versions/3.12/lib/python3.12/site-packages/flask/app.py", line 1484, in full_dispatch_request
    rv = self.dispatch_request()
         ^^^^^^^^^^^^^^^^^^^^^^^
  File "/Library/Frameworks/Python.framework/Versions/3.12/lib/python3.12/site-packages/flask/app.py", line 1458, in dispatch_request
    self.raise_routing_exception(req)
  File "/Library/Frameworks/Python.framework/Versions/3.12/lib/python3.12/site-packages/flask/app.py", line 1440, in raise_routing_exception
    raise request.routing_exception  # type: ignore
    ^^^^^^^^^^^^^^^^^^^^^^^^^^^^^^^
  File "/Library/Frameworks/Python.framework/Versions/3.12/lib/python3.12/site-packages/flask/ctx.py", line 353, in match_request
    result = self.url_adapter.match(return_rule=True)  # type: ignore
             ^^^^^^^^^^^^^^^^^^^^^^^^^^^^^^^^^^^^^^^^
  File "/Library/Frameworks/Python.framework/Versions/3.12/lib/python3.12/site-packages/werkzeug/routing/map.py", line 655, in match
    raise NotFound() from None
werkzeug.exceptions.NotFound: 404 Not Found: The requested URL was not found on the server. If you entered the URL manually please check your spelling and try again.
[2024-12-12 18:40:31,510] Exception: 404 Not Found: The requested URL was not found on the server. If you entered the URL manually please check your spelling and try again.
Traceback (most recent call last):
  File "/Library/Frameworks/Python.framework/Versions/3.12/lib/python3.12/site-packages/flask/app.py", line 1484, in full_dispatch_request
    rv = self.dispatch_request()
         ^^^^^^^^^^^^^^^^^^^^^^^
  File "/Library/Frameworks/Python.framework/Versions/3.12/lib/python3.12/site-packages/flask/app.py", line 1458, in dispatch_request
    self.raise_routing_exception(req)
  File "/Library/Frameworks/Python.framework/Versions/3.12/lib/python3.12/site-packages/flask/app.py", line 1440, in raise_routing_exception
    raise request.routing_exception  # type: ignore
    ^^^^^^^^^^^^^^^^^^^^^^^^^^^^^^^
  File "/Library/Frameworks/Python.framework/Versions/3.12/lib/python3.12/site-packages/flask/ctx.py", line 353, in match_request
    result = self.url_adapter.match(return_rule=True)  # type: ignore
             ^^^^^^^^^^^^^^^^^^^^^^^^^^^^^^^^^^^^^^^^
  File "/Library/Frameworks/Python.framework/Versions/3.12/lib/python3.12/site-packages/werkzeug/routing/map.py", line 655, in match
    raise NotFound() from None
werkzeug.exceptions.NotFound: 404 Not Found: The requested URL was not found on the server. If you entered the URL manually please check your spelling and try again.
[2024-12-12 18:40:31,511] Response: 500 INTERNAL SERVER ERROR - Data: An error occurred
[2024-12-12 18:40:31,512] 127.0.0.1 - - [12/Dec/2024 18:40:31] "[35m[1mGET /favicon.ico HTTP/1.1[0m" 500 -
[2024-12-12 18:40:44,987] Request: GET http://127.0.0.1:8000/films - Params: ImmutableMultiDict([]) - Body: 
[2024-12-12 18:40:44,990] Response: 200 OK - Data: [
  {
    "dateRelease": "rwerwet",
    "filmName": "qwrqwrq",
    "genre": "ewrwer",
    "id": 1,
    "urlImage": 234
  }
]

[2024-12-12 18:40:44,990] 127.0.0.1 - - [12/Dec/2024 18:40:44] "GET /films HTTP/1.1" 200 -
[2024-12-12 18:40:45,015] Request: GET http://127.0.0.1:8000/favicon.ico - Params: ImmutableMultiDict([]) - Body: 
[2024-12-12 18:40:45,015] Exception: 404 Not Found: The requested URL was not found on the server. If you entered the URL manually please check your spelling and try again.
Traceback (most recent call last):
  File "/Library/Frameworks/Python.framework/Versions/3.12/lib/python3.12/site-packages/flask/app.py", line 1484, in full_dispatch_request
    rv = self.dispatch_request()
         ^^^^^^^^^^^^^^^^^^^^^^^
  File "/Library/Frameworks/Python.framework/Versions/3.12/lib/python3.12/site-packages/flask/app.py", line 1458, in dispatch_request
    self.raise_routing_exception(req)
  File "/Library/Frameworks/Python.framework/Versions/3.12/lib/python3.12/site-packages/flask/app.py", line 1440, in raise_routing_exception
    raise request.routing_exception  # type: ignore
    ^^^^^^^^^^^^^^^^^^^^^^^^^^^^^^^
  File "/Library/Frameworks/Python.framework/Versions/3.12/lib/python3.12/site-packages/flask/ctx.py", line 353, in match_request
    result = self.url_adapter.match(return_rule=True)  # type: ignore
             ^^^^^^^^^^^^^^^^^^^^^^^^^^^^^^^^^^^^^^^^
  File "/Library/Frameworks/Python.framework/Versions/3.12/lib/python3.12/site-packages/werkzeug/routing/map.py", line 655, in match
    raise NotFound() from None
werkzeug.exceptions.NotFound: 404 Not Found: The requested URL was not found on the server. If you entered the URL manually please check your spelling and try again.
[2024-12-12 18:40:45,016] Response: 500 INTERNAL SERVER ERROR - Data: An error occurred
[2024-12-12 18:40:45,017] 127.0.0.1 - - [12/Dec/2024 18:40:45] "[35m[1mGET /favicon.ico HTTP/1.1[0m" 500 -
[2024-12-12 18:40:47,776] Request: GET http://127.0.0.1:8000/ - Params: ImmutableMultiDict([]) - Body: 
[2024-12-12 18:40:47,777] Exception: 404 Not Found: The requested URL was not found on the server. If you entered the URL manually please check your spelling and try again.
Traceback (most recent call last):
  File "/Library/Frameworks/Python.framework/Versions/3.12/lib/python3.12/site-packages/flask/app.py", line 1484, in full_dispatch_request
    rv = self.dispatch_request()
         ^^^^^^^^^^^^^^^^^^^^^^^
  File "/Library/Frameworks/Python.framework/Versions/3.12/lib/python3.12/site-packages/flask/app.py", line 1458, in dispatch_request
    self.raise_routing_exception(req)
  File "/Library/Frameworks/Python.framework/Versions/3.12/lib/python3.12/site-packages/flask/app.py", line 1440, in raise_routing_exception
    raise request.routing_exception  # type: ignore
    ^^^^^^^^^^^^^^^^^^^^^^^^^^^^^^^
  File "/Library/Frameworks/Python.framework/Versions/3.12/lib/python3.12/site-packages/flask/ctx.py", line 353, in match_request
    result = self.url_adapter.match(return_rule=True)  # type: ignore
             ^^^^^^^^^^^^^^^^^^^^^^^^^^^^^^^^^^^^^^^^
  File "/Library/Frameworks/Python.framework/Versions/3.12/lib/python3.12/site-packages/werkzeug/routing/map.py", line 655, in match
    raise NotFound() from None
werkzeug.exceptions.NotFound: 404 Not Found: The requested URL was not found on the server. If you entered the URL manually please check your spelling and try again.
[2024-12-12 18:40:47,778] Response: 500 INTERNAL SERVER ERROR - Data: An error occurred
[2024-12-12 18:40:47,778] 127.0.0.1 - - [12/Dec/2024 18:40:47] "[35m[1mGET / HTTP/1.1[0m" 500 -
[2024-12-12 18:40:47,803] Request: GET http://127.0.0.1:8000/favicon.ico - Params: ImmutableMultiDict([]) - Body: 
[2024-12-12 18:40:47,804] Exception: 404 Not Found: The requested URL was not found on the server. If you entered the URL manually please check your spelling and try again.
Traceback (most recent call last):
  File "/Library/Frameworks/Python.framework/Versions/3.12/lib/python3.12/site-packages/flask/app.py", line 1484, in full_dispatch_request
    rv = self.dispatch_request()
         ^^^^^^^^^^^^^^^^^^^^^^^
  File "/Library/Frameworks/Python.framework/Versions/3.12/lib/python3.12/site-packages/flask/app.py", line 1458, in dispatch_request
    self.raise_routing_exception(req)
  File "/Library/Frameworks/Python.framework/Versions/3.12/lib/python3.12/site-packages/flask/app.py", line 1440, in raise_routing_exception
    raise request.routing_exception  # type: ignore
    ^^^^^^^^^^^^^^^^^^^^^^^^^^^^^^^
  File "/Library/Frameworks/Python.framework/Versions/3.12/lib/python3.12/site-packages/flask/ctx.py", line 353, in match_request
    result = self.url_adapter.match(return_rule=True)  # type: ignore
             ^^^^^^^^^^^^^^^^^^^^^^^^^^^^^^^^^^^^^^^^
  File "/Library/Frameworks/Python.framework/Versions/3.12/lib/python3.12/site-packages/werkzeug/routing/map.py", line 655, in match
    raise NotFound() from None
werkzeug.exceptions.NotFound: 404 Not Found: The requested URL was not found on the server. If you entered the URL manually please check your spelling and try again.
[2024-12-12 18:40:47,805] Response: 500 INTERNAL SERVER ERROR - Data: An error occurred
[2024-12-12 18:40:47,805] 127.0.0.1 - - [12/Dec/2024 18:40:47] "[35m[1mGET /favicon.ico HTTP/1.1[0m" 500 -
[2024-12-12 18:42:12,351] Request: GET http://127.0.0.1:8000/films - Params: ImmutableMultiDict([]) - Body: 
[2024-12-12 18:42:12,358] Response: 200 OK - Data: [
  {
    "dateRelease": "rwerwet",
    "filmName": "qwrqwrq",
    "genre": "ewrwer",
    "id": 1,
    "urlImage": 234
  }
]

[2024-12-12 18:42:12,359] 127.0.0.1 - - [12/Dec/2024 18:42:12] "GET /films HTTP/1.1" 200 -
[2024-12-12 18:44:57,760] Request: GET http://127.0.0.1:8000/set_log_level/DEBUG - Params: ImmutableMultiDict([]) - Body: 
[2024-12-12 18:44:57,761] Response: 200 OK - Data: Log level set to DEBUG
[2024-12-12 18:44:57,761] 127.0.0.1 - - [12/Dec/2024 18:44:57] "GET /set_log_level/DEBUG HTTP/1.1" 200 -
[2024-12-12 18:46:18,383] Request: GET http://127.0.0.1:8000/some_route - Params: ImmutableMultiDict([]) - Body: 
[2024-12-12 18:46:18,384] some_route took 0.0000 seconds
[2024-12-12 18:46:18,384] Response: 200 OK - Data: Hello, World!
[2024-12-12 18:46:18,384] 127.0.0.1 - - [12/Dec/2024 18:46:18] "GET /some_route HTTP/1.1" 200 -
[2024-12-12 18:46:44,564] Request: GET http://127.0.0.1:8000/login/ - Params: ImmutableMultiDict([]) - Body: 
[2024-12-12 18:46:44,565] Exception: 404 Not Found: The requested URL was not found on the server. If you entered the URL manually please check your spelling and try again.
Traceback (most recent call last):
  File "/Library/Frameworks/Python.framework/Versions/3.12/lib/python3.12/site-packages/flask/app.py", line 1484, in full_dispatch_request
    rv = self.dispatch_request()
         ^^^^^^^^^^^^^^^^^^^^^^^
  File "/Library/Frameworks/Python.framework/Versions/3.12/lib/python3.12/site-packages/flask/app.py", line 1458, in dispatch_request
    self.raise_routing_exception(req)
  File "/Library/Frameworks/Python.framework/Versions/3.12/lib/python3.12/site-packages/flask/app.py", line 1440, in raise_routing_exception
    raise request.routing_exception  # type: ignore
    ^^^^^^^^^^^^^^^^^^^^^^^^^^^^^^^
  File "/Library/Frameworks/Python.framework/Versions/3.12/lib/python3.12/site-packages/flask/ctx.py", line 353, in match_request
    result = self.url_adapter.match(return_rule=True)  # type: ignore
             ^^^^^^^^^^^^^^^^^^^^^^^^^^^^^^^^^^^^^^^^
  File "/Library/Frameworks/Python.framework/Versions/3.12/lib/python3.12/site-packages/werkzeug/routing/map.py", line 655, in match
    raise NotFound() from None
werkzeug.exceptions.NotFound: 404 Not Found: The requested URL was not found on the server. If you entered the URL manually please check your spelling and try again.
[2024-12-12 18:46:44,566] Response: 500 INTERNAL SERVER ERROR - Data: An error occurred
[2024-12-12 18:46:44,566] 127.0.0.1 - - [12/Dec/2024 18:46:44] "[35m[1mGET /login/ HTTP/1.1[0m" 500 -
[2024-12-12 18:47:46,903] Request: GET http://127.0.0.1:8000/login - Params: ImmutableMultiDict([]) - Body: 
[2024-12-12 18:47:46,903] Successful login - User: username123 - IP: 127.0.0.1
[2024-12-12 18:47:46,904] Response: 200 OK - Data: Logged in
[2024-12-12 18:47:46,904] 127.0.0.1 - - [12/Dec/2024 18:47:46] "GET /login HTTP/1.1" 200 -
